Workbook

Sheet README
A1: This excel sheet contains the results of a 1D denitrification problem without the whole path (2 redox reactions only). The input and output files can be found in the folder "denit_2reacts_case1".
A3: The infiltration water is in equilibrium with atmospheric O2 & CO2 as well as with calcite
A5: We assume that the partial pressure of gases is constant
A6: We also assume that water has activity=1
A8: The domain is discretised by cells, who begin and end in the domain's boundary
A10: The initial water is in equilibrium with calcite
A12: This problem has been simulated with the code REMIX, and the results are shown in the sheet "results"
A14: the BCs are prescribed mass flux at the inlet, and zero dispersive flux at the outlet
A16: concentrations of aqueous species are expressed in molalities
A18: The equilibrium reaction rates are computed using ordinary least squares method with the concentrations of variable activity species
A20: the kinetic reaction rates are computed using Monod expressions
A22: both transport and reactions are solved using Euler fully implicit

Sheet transport
A1: Delta_x | B1: =$B$3/($E$6) -> 0.1 | C1: m | D1: theta_t | E1: 1 | G1: t_c | H1: =$B$6*$B$4/($B$5^2) -> 2.5 | I1: d | K1: T_{i,i-1} | L1: =$B$5/(2*$B$1)+$B$6/($B$1^2) -> 21 | M1: 1/d | O1: A_{i,i-1} | P1: =-$B$2*L1/$B$4 -> -0.42
A2: Delta_t | B2: 0.01 | C2: d | G2: L_c | H2: =$B$7 -> 1 | I2: m | K2: T_{i,i+1} | L2: =-$B$5/(2*$B$1)+$B$6/($B$1^2) -> 19 | O2: A_{i,i+1} | P2: =-$B$2*L2/$B$4 -> -0.38
A3: L | B3: 1 | C3: m | D3: Courant | E3: =B5*B2/(B4*B1) -> 0.04 | K3: T_{i,i} | L3: =-L2-L1 -> -40 | O3: A_{i,i} | P3: =1-$B$2*L3/$B$4 -> 1.8
A4: phi | B4: 0.5 | D4: Peclet grid | E4: =ABS(B5)*B1/B6 -> 0.1 | G4: q_inf | H4: =$B$5 -> 0.2 | I4: =C5 -> m/d | K4: T_{1,1} | L4: =-$B$5/(2*$B$1)-$B$6/($B$1^2) -> -21
A5: q | B5: 0.2 | C5: m/d | K5: T_{n,n} | L5: =-$L$1 -> -21
A6: D | B6: =$B$5*$B$7 -> 0.2 | C6: m^2/d | D6: num cells | E6: 10 | G6: transport approach | H6: Eulerian
A7: long disp | B7: 1 | C7: m
A8: initial target waters
A9: tar wat ind | B9: init wat type | C9: init min zone
A10: 1 | B10: 1 | D10: inflow
A11: 2 | B11: 2 | C11: 1 | D11: domain
A12: 3 | B12: 2 | C12: 1
A13: 4 | B13: 2 | C13: 1
A14: 5 | B14: 2 | C14: 1
A15: 6 | B15: 2 | C15: 1
A16: 7 | B16: 2 | C16: 1
A17: 8 | B17: 2 | C17: 1
A18: 9 | B18: 2 | C18: 1
A19: 10 | B19: 2 | C19: 1
A20: 11 | B20: 2 | C20: 1
A21: 12 | B21: 2 | D21: outflow
A22: BC inflow
A28: BC outflow

Sheet lambdas
A1: sum | B1: lambdas | C1: inf | D1: 1 | E1: 2 | F1: 3 | G1: 4 | H1: 5 | I1: 6 | J1: 7 | K1: 8 | L1: 9 | M1: 10 | N1: out
A2: =SUM(C2:N2) -> 1 | B2: 1 | C2: 0.030155137 | D2: 0.75387844 | E2: 0.16787472 | F2: 0.037382579 | G2: 0.0083244056 | H2: 0.0018536906 | I2: 0.00041278321 | J2: 9.1922237e-05 | K2: 2.0481924e-05 | L2: 4.6119372e-06 | M2: 1.2341804e-06 | N2: 0
A3: =SUM(C3:N3) -> 1 | B3: 2 | C3: 0.0074218296 | D3: 0.18554574 | E3: 0.62732131 | F3: 0.1396928 | G3: 0.03110699 | H3: 0.0069269491 | I3: 0.0015425057 | J3: 0.00034349888 | K3: 7.6537717e-05 | L3: 1.7234081e-05 | M3: 4.6119372e-06 | N3: 0
A4: =SUM(C4:N4) -> 1 | B4: 3 | C4: 0.0018266723 | D4: 0.045666807 | E4: 0.1543973 | F4: 0.62038513 | G4: 0.13814824 | H4: 0.030763048 | I4: 0.0068503717 | J4: 0.0015255017 | K4: 0.00033990916 | L4: 7.6537717e-05 | M4: 2.0481924e-05 | N4: 0
A5: =SUM(C5:N5) -> 1 | B5: 4 | C5: 0.00044958344 | D5: 0.011239586 | E5: 0.038000505 | F5: 0.15269016 | G5: 0.62000498 | H5: 0.1380636 | I5: 0.030744254 | J5: 0.0068464041 | K5: 0.0015255017 | L5: 0.00034349888 | M5: 9.1922237e-05 | N5: 0
A6: =SUM(C6:N6) -> 1 | B6: 5 | C6: 0.00011065219 | D6: 0.0027663048 | E6: 0.0093527447 | F6: 0.037580344 | G6: 0.15259661 | H6: 0.61998421 | I6: 0.13805922 | J6: 0.030744254 | K6: 0.0068503717 | L6: 0.0015425057 | M6: 0.00041278321 | N6: 0
A7: =SUM(C7:N7) -> 1 | B7: 6 | C7: 2.723394e-05 | D7: 0.0006808485 | E7: 0.0023019164 | F7: 0.0092493501 | G7: 0.037557386 | H7: 0.15259176 | I7: 0.61998421 | J7: 0.1380636 | K7: 0.030763048 | L7: 0.0069269491 | M7: 0.0018536906 | N7: 0
A8: =SUM(C8:N8) -> 1 | B8: 7 | C8: 6.7030852e-06 | D8: 0.00016757713 | E8: 0.00056657029 | F8: 0.002276541 | G8: 0.0092439931 | H8: 0.037557386 | I8: 0.15259661 | J8: 0.62000498 | K8: 0.13814824 | L8: 0.03110699 | M8: 0.0083244056 | N8: 0
A9: =SUM(C9:N9) -> 1 | B9: 8 | C9: 1.6507853e-06 | D9: 4.1269633e-05 | E9: 0.00013953067 | F9: 0.00056064937 | G9: 0.002276541 | H9: 0.0092493501 | I9: 0.037580344 | J9: 0.15269016 | K9: 0.62038513 | L9: 0.1396928 | M9: 0.037382579 | N9: 0
A10: =SUM(C10:N10) -> 1 | B10: 9 | C10: 4.1083641e-07 | D10: 1.027091e-05 | E10: 3.4725459e-05 | F10: 0.00013953067 | G10: 0.00056657029 | H10: 0.0023019164 | I10: 0.0093527447 | J10: 0.038000505 | K10: 0.1543973 | L10: 0.62732131 | M10: 0.16787472 | N10: 0
A11: =SUM(C11:N11) -> 1 | B11: 10 | C11: 1.2151499e-07 | D11: 3.0378749e-06 | E11: 1.027091e-05 | F11: 4.1269633e-05 | G11: 0.00016757713 | H11: 0.0006808485 | I11: 0.0027663048 | J11: 0.011239586 | K11: 0.045666807 | L11: 0.18554574 | M11: 0.75387844 | N11: 0

Sheet chem
A1: theta_r | B1: 1 | E1: ='wat types'!$A$3 -> cl- | F1: ='wat types'!$A$4 -> ch2o(aq) | G1: ='wat types'!$A$5 -> h+ | H1: ='wat types'!$A$6 -> no3- | I1: ='wat types'!$A$7 -> n2(aq)(p) | J1: ='wat types'!$A$8 -> ca+2 | K1: ='wat types'!$A$9 -> hco3- | L1: ='wat types'!$A$10 -> o2(aq) | M1: ='wat types'!$A$11 -> co3-2 | N1: =L30 -> h2o
D2: S_K | E2: 0 | F2: -1 | G2: 1 | H2: 0 | I2: 0 | J2: 0 | K2: 1 | L2: -1 | M2: 0 | N2: 0
A3: aqueous species | B3: ='wat types'!$A$2 -> h2o(p) | E3: 0 | F3: -1 | G3: 0.2 | H3: -0.8 | I3: 0.4 | J3: 0 | K3: 1 | L3: 0 | M3: 0 | N3: 0.4
B4: ='wat types'!$A$3 -> cl-
B5: ='wat types'!$A$4 -> ch2o(aq) | D5: mu_1 | E5: 0.5 | F5: K_DOC | G5: 0.001 | H5: K_O2 | I5: 1e-05
B6: ='wat types'!$A$5 -> h+ | D6: mu_2 | E6: 2 | F6: K_DOC | G6: 0.0014 | H6: K_NO3 | I6: 0.0059 | J6: I_O2 | K6: 2.52e-05
B7: ='wat types'!$A$6 -> no3-
B8: ='wat types'!$A$7 -> n2(aq)(p)
B9: ='wat types'!$A$8 -> ca+2
B10: ='wat types'!$A$9 -> hco3-
B11: ='wat types'!$A$10 -> o2(aq)
B12: ='wat types'!$A$11 -> co3-2
A14: minerals | B14: calcite
C15: part press
A16: gases | B16: co2(g) | C16: 0.00035
B17: o2(g) | C17: 0.2
A19: act coeffs model | B19: ideal
G20: K | H20: K master25
A21: equilibrium reactions | B21: calcite | G21: =1/H21 -> 0.014167721 | H21: =10^(1.8487) -> 70.582982
B22: co2(g) | G22: =1/(H22*C16) -> 1.8600814e+11 | H22: =10^(-7.8136) -> 1.5360311e-08
B23: o2(g) | G23: =1/(H23*C17) -> 3953.3931 | H23: =10^(-2.898) -> 0.0012647363
B24: co3-2 | G24: =1/H24 -> 4.6902933e-11 | H24: =10^(10.3288) -> 2.1320628e+10
A26: kinetic reactions | B26: aerobic oxidation of DOC
B27: denitrification
A29: reactive zone domain
C30: ='wat types'!$A$3 -> cl- | D30: ='wat types'!$A$4 -> ch2o(aq) | E30: ='wat types'!$A$5 -> h+ | F30: ='wat types'!$A$6 -> no3- | G30: ='wat types'!$A$7 -> n2(aq)(p) | H30: ='wat types'!$A$8 -> ca+2 | I30: =$B$11 -> o2(aq) | J30: =$B$10 -> hco3- | K30: ='wat types'!$A$11 -> co3-2 | L30: h2o | M30: calcite | N30: K
B31: S_e | C31: 0 | D31: 0 | E31: 1 | F31: 0 | G31: 0 | H31: -1 | I31: 0 | J31: -1 | K31: 0 | L31: 0 | M31: 1 | N31: =1/H21 -> 0.014167721
C32: 0 | D32: 0 | E32: 1 | F32: 0 | G32: 0 | H32: 0 | I32: 0 | J32: -1 | K32: 1 | L32: 0 | M32: 0 | N32: =1/H24 -> 4.6902933e-11
B34: U | C34: 1 | D34: 0 | E34: 0 | F34: 0 | G34: 0 | H34: 0 | I34: 0 | J34: 0 | K34: 0
C35: 0 | D35: 1 | E35: 0 | F35: 0 | G35: 0 | H35: 0 | I35: 0 | J35: 0 | K35: 0
C36: 0 | D36: 0 | E36: 1 | F36: 0 | G36: 0 | H36: 0 | I36: 0 | J36: 1 | K36: 0
C37: 0 | D37: 0 | E37: 0 | F37: 1 | G37: 0 | H37: 0 | I37: 0 | J37: 0 | K37: 0
C38: 0 | D38: 0 | E38: 0 | F38: 0 | G38: 1 | H38: 0 | I38: 0 | J38: 0 | K38: 0
C39: 0 | D39: 0 | E39: 0 | F39: 0 | G39: 0 | H39: 1 | I39: 0 | J39: -1 | K39: -1
C40: 0 | D40: 0 | E40: 0 | F40: 0 | G40: 0 | H40: 0 | I40: 1 | J40: 0 | K40: 0
B42: eq reactions | C42: calcite
C43: co3-2
B45: prim species | C45: ='wat types'!$A$3 -> cl-
C46: ='wat types'!$A$4 -> ch2o(aq)
C47: ='wat types'!$A$5 -> h+
...

Sheet wat types
A1: aq species conc | B1: infiltration water | C1: initial water
A2: h2o(p) | B2: 55.5556 | C2: 55.5556
A3: cl- | B3: 0.001 | C3: 1e-16
A4: ch2o(aq) | B4: 0.002 | C4: 1e-05
A5: h+ | B5: 1e-08 | C5: 1e-07
A6: no3- | B6: 0.001 | C6: 1e-05
A7: n2(aq)(p) | B7: 1e-16 | C7: 1e-16
A8: ca+2 | B8: 0.0013129 | C8: 0.0070583
A9: hco3- | B9: 0.000537611 | C9: 0.001
A10: o2(aq) | B10: 0.000252947 | C10: 1e-06
A11: co3-2 | B11: 2.52155e-06 | C11: 4.69029e-07
A12: err abs
A13: calcite | B13: =ABS(1-B8*B9/(B5*chem!$H$21)) -> 4.7314496e-07 | C13: =ABS(1-C8*C9/(C5*chem!$H$21)) -> 2.6088467e-07
A14: co2(g) | B14: =ABS(1-B5*B9/(chem!$C$16*chem!$H$22)) -> 2.3449161e-07
A15: o2(g) | B15: =ABS(1-B10/(chem!$C$17*chem!$H$23)) -> 1.0654166e-06

Sheet results
A1: cell | B1: 1 | C1: 2 | D1: 3 | E1: 4 | F1: 5 | G1: 6 | H1: 7 | I1: 8 | J1: 9 | K1: 10
A2: x | B2: =transport!$B$1*(B$1-0.5) -> 0.05 | C2: =transport!$B$1*(C$1-0.5) -> 0.15 | D2: =transport!$B$1*(D$1-0.5) -> 0.25 | E2: =transport!$B$1*(E$1-0.5) -> 0.35 | F2: =transport!$B$1*(F$1-0.5) -> 0.45 | G2: =transport!$B$1*(G$1-0.5) -> 0.55 | H2: =transport!$B$1*(H$1-0.5) -> 0.65 | I2: =transport!$B$1*(I$1-0.5) -> 0.75 | ... K2: =transport!$B$1*(K$1-0.5) -> 0.95
A5: aq species conc | B5: t=0
A6: ='wat types'!$A$2 -> h2o(p) | B6: 55.5556 | C6: 55.5556 | D6: 55.5556 | E6: 55.5556 | F6: 55.5556 | G6: 55.5556 | H6: 55.5556 | I6: 55.5556 | J6: 55.5556 | K6: 55.5556
A7: ='wat types'!$A$3 -> cl- | B7: 1e-16 | C7: 1e-16 | D7: 1e-16 | E7: 1e-16 | F7: 1e-16 | G7: 1e-16 | H7: 1e-16 | I7: 1e-16 | J7: 1e-16 | K7: 1e-16
A8: ='wat types'!$A$4 -> ch2o(aq) | B8: 1e-05 | C8: 1e-05 | D8: 1e-05 | E8: 1e-05 | F8: 1e-05 | G8: 1e-05 | H8: 1e-05 | I8: 1e-05 | J8: 1e-05 | K8: 1e-05
A9: ='wat types'!$A$5 -> h+ | B9: 1e-07 | C9: 1e-07 | D9: 1e-07 | E9: 1e-07 | F9: 1e-07 | G9: 1e-07 | H9: 1e-07 | I9: 1e-07 | J9: 1e-07 | K9: 1e-07
A10: ='wat types'!$A$6 -> no3- | B10: 1e-05 | C10: 1e-05 | D10: 1e-05 | E10: 1e-05 | F10: 1e-05 | G10: 1e-05 | H10: 1e-05 | I10: 1e-05 | J10: 1e-05 | K10: 1e-05
A11: ='wat types'!$A$7 -> n2(aq)(p) | B11: 1e-16 | C11: 1e-16 | D11: 1e-16 | E11: 1e-16 | F11: 1e-16 | G11: 1e-16 | H11: 1e-16 | I11: 1e-16 | J11: 1e-16 | K11: 1e-16
A12: ='wat types'!$A$8 -> ca+2 | B12: 0.0070583 | C12: 0.0070583 | D12: 0.0070583 | E12: 0.0070583 | F12: 0.0070583 | G12: 0.0070583 | H12: 0.0070583 | I12: 0.0070583 | J12: 0.0070583 | K12: 0.0070583
A13: ='wat types'!$A$9 -> hco3- | B13: 0.001 | C13: 0.001 | D13: 0.001 | E13: 0.001 | F13: 0.001 | G13: 0.001 | H13: 0.001 | I13: 0.001 | J13: 0.001 | K13: 0.001
A14: ='wat types'!$A$10 -> o2(aq) | B14: 1e-06 | C14: 1e-06 | D14: 1e-06 | E14: 1e-06 | F14: 1e-06 | G14: 1e-06 | H14: 1e-06 | I14: 1e-06 | J14: 1e-06 | K14: 1e-06
A15: ='wat types'!$A$11 -> co3-2 | B15: 4.69029e-07 | C15: 4.69029e-07 | D15: 4.69029e-07 | E15: 4.69029e-07 | F15: 4.69029e-07 | G15: 4.69029e-07 | H15: 4.69029e-07 | I15: 4.69029e-07 | J15: 4.69029e-07 | K15: 4.69029e-07
A16: vol frac
A17: calcite | B17: 0.5 | C17: 0.5 | D17: 0.5 | E17: 0.5 | F17: 0.5 | G17: 0.5 | H17: 0.5 | I17: 0.5 | J17: 0.5 | K17: 0.5
A18: aq species conc | B18: t=0.01d | L18: error abs
A19: ='wat types'!$A$2 -> h2o(p) | B19: 55.5556 | C19: 55.5556 | D19: 55.5556 | E19: 55.5556 | F19: 55.5556 | G19: 55.5556 | H19: 55.5556 | I19: 55.5556 | J19: 55.5556 | K19: 55.5556
A20: ='wat types'!$A$3 -> cl- | B20: 3.01551e-05 | C20: 7.42183e-06 | D20: 1.82667e-06 | E20: 4.49583e-07 | F20: 1.10652e-07 | G20: 2.72339e-08 | H20: 6.70309e-09 | I20: 1.65079e-09 | J20: 4.10837e-10 | K20: 1.21515e-10 | L20: =ABS(B20-SUMPRODUCT($B$7:$K$7,lambdas!$D$2:$M$2)-'wat types'!$B$3*lambdas!$C$2) -> 3.748921e-11 | M20: =ABS(C20-SUMPRODUCT($B$7:$K$7,lambdas!$D$3:$M$3)-'wat types'!$B$3*lambdas!$C$3) -> 4.3532049e-13 | N20: =ABS(D20-SUMPRODUCT($B$7:$K$7,lambdas!$D$4:$M$4)-'wat types'!$B$3*lambdas!$C$4) -> 2.2917234e-12 | O20: =ABS(E20-SUMPRODUCT($B$7:$K$7,lambdas!$D$5:$M$5)-'wat types'!$B$3*lambdas!$C$5) -> 4.4167585e-13 | P20: =ABS(F20-SUMPRODUCT($B$7:$K$7,lambdas!$D$6:$M$6)-'wat types'!$B$3*lambdas!$C$6) -> 1.9050707e-13 | Q20: =ABS(G20-SUMPRODUCT($B$7:$K$7,lambdas!$D$7:$M$7)-'wat types'!$B$3*lambdas!$C$7) -> 4.0286502e-14
A21: ='wat types'!$A$4 -> ch2o(aq) | B21: 5.71576e-05 | C21: 2.13267e-05 | D21: 1.20588e-05 | E21: 9.73799e-06 | F21: 9.16371e-06 | G21: 9.02216e-06 | H21: 8.98731e-06 | I21: 8.97873e-06 | J21: 8.97663e-06 | K21: 8.97614e-06
A22: ='wat types'!$A$5 -> h+ | B22: 9.84654e-08 | C22: 9.97123e-08 | D22: 1.00074e-07 | E22: 1.00169e-07 | F22: 1.00192e-07 | G22: 1.00198e-07 | H22: 1.002e-07 | I22: 1.002e-07 | J22: 1.002e-07 | K22: 1.002e-07
A23: ='wat types'!$A$6 -> no3- | B23: 3.61901e-05 | C23: 1.66825e-05 | D23: 1.15443e-05 | E23: 1.02549e-05 | F23: 9.93594e-06 | G23: 9.85734e-06 | H23: 9.83799e-06 | I23: 9.83323e-06 | J23: 9.83206e-06 | K23: 9.83179e-06
A24: ='wat types'!$A$7 -> n2(aq)(p) | B24: 1.83174e-06 | C24: 3.32534e-07 | D24: 1.3205e-07 | E24: 9.51071e-08 | F24: 8.68047e-08 | G24: 8.48097e-08 | H24: 8.43216e-08 | I24: 8.42017e-08 | J24: 8.41723e-08 | K24: 8.41654e-08
A25: ='wat types'!$A$8 -> ca+2 | B25: 0.00689418 | C25: 0.00701842 | D25: 0.00704911 | E25: 0.00705668 | F25: 0.00705854 | G25: 0.007059 | H25: 0.00705912 | I25: 0.00705914 | J25: 0.00705915 | K25: 0.00705915
A26: ='wat types'!$A$9 -> hco3- | B26: 0.00100809 | C26: 0.00100279 | D26: 0.00100204 | E26: 0.00100192 | F26: 0.00100189 | G26: 0.00100188 | H26: 0.00100188 | I26: 0.00100188 | J26: 0.00100188 | K26: 0.00100188
A27: ='wat types'!$A$10 -> o2(aq) | B27: 3.25771e-07 | C27: 2.58503e-07 | D27: 2.14045e-07 | E27: 1.94357e-07 | F27: 1.88401e-07 | G27: 1.8685e-07 | H27: 1.86462e-07 | I27: 1.86366e-07 | J27: 1.86343e-07 | K27: 1.86337e-07
A28: ='wat types'!$A$11 -> co3-2 | B28: 4.80195e-07 | C28: 4.71694e-07 | D28: 4.69641e-07 | E28: 4.69137e-07 | F28: 4.69013e-07 | G28: 4.68982e-07 | H28: 4.68975e-07 | I28: 4.68973e-07 | J28: 4.68973e-07 | K28: 4.68973e-07
A29: r_eq
A30: calcite | B30: -0.00311993 | C30: -0.000888482 | D30: -0.000413888 | E30: -0.000304241 | F30: -0.000277871 | G30: -0.000271424 | H30: -0.000269839 | I30: -0.00026945 | J30: -0.000269354 | K30: -0.000269332 | L30: =ABS(1-B25*B26/(B22*chem!$H$21)) -> 3.971069e-06 | M30: =ABS(1-C25*C26/(C22*chem!$H$21)) -> 1.4147508e-06 | N30: =ABS(1-D25*D26/(D22*chem!$H$21)) -> 4.4050034e-06 | O30: =ABS(1-E25*E26/(E22*chem!$H$21)) -> 3.0311811e-07 | P30: =ABS(1-F25*F26/(F22*chem!$H$21)) -> 4.3198791e-06 | Q30: =ABS(1-G25*G26/(G22*chem!$H$21)) -> 3.773825e-07 | R30: =ABS(1-H25*H26/(H22*chem!$H$21)) -> 3.3382255e-06 | S30: =ABS(1-I25*I26/(I22*chem!$H$21)) -> 5.0502064e-07 | ... U30: =ABS(1-K25*K26/(K22*chem!$H$21)) -> 9.115818e-07
A31: co3-2 | B31: -5.23061e-06 | C31: -1.26626e-06 | D31: -3.14381e-07 | E31: -8.15632e-08 | F31: -2.43536e-08 | G31: -1.02787e-08 | H31: -6.81495e-09 | I31: -5.9626e-09 | J31: -5.75341e-09 | K31: -5.7046e-09 | L31: =ABS(1-B22*B28/(B26*chem!$N$32)) -> 4.5510767e-06 | M31: =ABS(1-C22*C28/(C26*chem!$N$32)) -> 2.0918368e-06 | N31: =ABS(1-D22*D28/(D26*chem!$N$32)) -> 5.0769669e-06 | O31: =ABS(1-E22*E28/(E26*chem!$N$32)) -> 4.9340293e-08 | P31: =ABS(1-F22*F28/(F26*chem!$N$32)) -> 4.8708229e-06 | Q31: =ABS(1-G22*G28/(G26*chem!$N$32)) -> 1.1048544e-06 | R31: =ABS(1-H22*H28/(H26*chem!$N$32)) -> 3.9293744e-06 | S31: =ABS(1-I22*I28/(I26*chem!$N$32)) -> 3.3526201e-07 | ... U31: =ABS(1-K22*K28/(K26*chem!$N$32)) -> 3.3526201e-07
A32: rk
A33: oxid aer | B33: 0.000852892 | C33: 0.000263093 | D33: 0.000124846 | E33: 9.19328e-05 | F33: 8.3957e-05 | G33: 8.20034e-05 | H33: 8.15232e-05 | I33: 8.14051e-05 | J33: 8.13761e-05 | K33: 8.13693e-05 | L33: =ABS(B33-chem!$E$5*B21*B27/((chem!$G$5+B21)*(chem!$I$5+B27))) -> 2.8235413e-10 | M33: =ABS(C33-chem!$E$5*C21*C27/((chem!$G$5+C21)*(chem!$I$5+C27))) -> 7.7735229e-10 | N33: =ABS(D33-chem!$E$5*D21*D27/((chem!$G$5+D21)*(chem!$I$5+D27))) -> 2.9875018e-10 | O33: =ABS(E33-chem!$E$5*E21*E27/((chem!$G$5+E21)*(chem!$I$5+E27))) -> 1.0441802e-10 | P33: =ABS(F33-chem!$E$5*F21*F27/((chem!$G$5+F21)*(chem!$I$5+F27))) -> 4.1479248e-12 | Q33: =ABS(G33-chem!$E$5*G21*G27/((chem!$G$5+G21)*(chem!$I$5+G27))) -> 2.183334e-10 | R33: =ABS(H33-chem!$E$5*H21*H27/((chem!$G$5+H21)*(chem!$I$5+H27))) -> 4.2705166e-11 | S33: =ABS(I33-chem!$E$5*I21*I27/((chem!$G$5+I21)*(chem!$I$5+I27))) -> 2.4392389e-10 | ... U33: =ABS(K33-chem!$E$5*K21*K27/((chem!$G$5+K21)*(chem!$I$5+K27))) -> 1.4898001e-10
A34: denit | B34: 0.000472173 | C34: 8.37551e-05 | D34: 3.3073e-05 | E34: 2.37875e-05 | F34: 2.17036e-05 | G34: 2.1203e-05 | H34: 2.10805e-05 | I34: 2.10505e-05 | J34: 2.10431e-05 | K34: 2.10414e-05 | L34: =ABS(B34-chem!$E$6*results!B21*results!B23*chem!$K$6/((chem!$G$6+results!B21)*(chem!$I$6+results!B23)*(chem!$K$6+results!B27))) -> 4.3263508e-11 | M34: =ABS(C34-chem!$E$6*results!C21*results!C23*chem!$K$6/((chem!$G$6+results!C21)*(chem!$I$6+results!C23)*(chem!$K$6+results!C27))) -> 1.8781702e-10 | N34: =ABS(D34-chem!$E$6*results!D21*results!D23*chem!$K$6/((chem!$G$6+results!D21)*(chem!$I$6+results!D23)*(chem!$K$6+results!D27))) -> 8.5086173e-11 | O34: =ABS(E34-chem!$E$6*results!E21*results!E23*chem!$K$6/((chem!$G$6+results!E21)*(chem!$I$6+results!E23)*(chem!$K$6+results!E27))) -> 3.578249e-11 | P34: =ABS(F34-chem!$E$6*results!F21*results!F23*chem!$K$6/((chem!$G$6+results!F21)*(chem!$I$6+results!F23)*(chem!$K$6+results!F27))) -> 2.5795169e-11 | Q34: =ABS(G34-chem!$E$6*results!G21*results!G23*chem!$K$6/((chem!$G$6+results!G21)*(chem!$I$6+results!G23)*(chem!$K$6+results!G27))) -> 7.495063e-12 | R34: =ABS(H34-chem!$E$6*results!H21*results!H23*chem!$K$6/((chem!$G$6+results!H21)*(chem!$I$6+results!H23)*(chem!$K$6+results!H27))) -> 4.3263516e-11 | S34: =ABS(I34-chem!$E$6*results!I21*results!I23*chem!$K$6/((chem!$G$6+results!I21)*(chem!$I$6+results!I23)*(chem!$K$6+results!I27))) -> 4.6998569e-11 | ... U34: =ABS(K34-chem!$E$6*results!K21*results!K23*chem!$K$6/((chem!$G$6+results!K21)*(chem!$I$6+results!K23)*(chem!$K$6+results!K27))) -> 3.3145677e-11
A35: aq species conc | B35: t=0.02d | L35: error abs
A36: ='wat types'!$A$2 -> h2o(p) | B36: 55.5556 | C36: 55.5556 | D36: 55.5556 | E36: 55.5556 | F36: 55.5556 | G36: 55.5556 | H36: 55.5556 | I36: 55.5556 | J36: 55.5556 | K36: 55.5556
A37: ='wat types'!$A$3 -> cl- | B37: 5.42066e-05 | C37: 1.79428e-05 | D37: 5.54862e-06 | E37: 1.64437e-06 | F37: 4.73317e-07 | G37: 1.33379e-07 | H37: 3.69852e-08 | I37: 1.01349e-08 | J37: 2.78503e-09 | K37: 9.09315e-10 | L37: =ABS(B37-SUMPRODUCT($B$20:$K$20,lambdas!$D$2:$M$2)-'wat types'!$B$3*lambdas!$C$2) -> 8.6935213e-14 | M37: =ABS(C37-SUMPRODUCT($B$20:$K$20,lambdas!$D$3:$M$3)-'wat types'!$B$3*lambdas!$C$3) -> 2.0727769e-11 | N37: =ABS(D37-SUMPRODUCT($B$20:$K$20,lambdas!$D$4:$M$4)-'wat types'!$B$3*lambdas!$C$4) -> 6.6711527e-13 | O37: =ABS(E37-SUMPRODUCT($B$20:$K$20,lambdas!$D$5:$M$5)-'wat types'!$B$3*lambdas!$C$5) -> 1.3328165e-12 | P37: =ABS(F37-SUMPRODUCT($B$20:$K$20,lambdas!$D$6:$M$6)-'wat types'!$B$3*lambdas!$C$6) -> 5.5575785e-14 | Q37: =ABS(G37-SUMPRODUCT($B$20:$K$20,lambdas!$D$7:$M$7)-'wat types'!$B$3*lambdas!$C$7) -> 4.215281e-13
A38: ='wat types'!$A$4 -> ch2o(aq) | B38: 8.95782e-05 | C38: 3.67492e-05 | D38: 1.75267e-05 | E38: 1.12862e-05 | F38: 9.39297e-06 | G38: 8.84146e-06 | H38: 8.68494e-06 | I38: 8.64134e-06 | J38: 8.62941e-06 | K38: 8.62636e-06
A39: ='wat types'!$A$5 -> h+ | B39: 9.77903e-08 | C39: 9.92938e-08 | D39: 9.99344e-08 | E39: 1.00158e-07 | F39: 1.00228e-07 | G39: 1.00249e-07 | H39: 1.00255e-07 | I39: 1.00256e-07 | J39: 1.00257e-07 | K39: 1.00257e-07
A40: ='wat types'!$A$6 -> no3- | B40: 5.25978e-05 | C40: 2.49213e-05 | D40: 1.45421e-05 | E40: 1.11321e-05 | F40: 1.00937e-05 | G40: 9.79073e-06 | H40: 9.70464e-06 | I40: 9.68064e-06 | J40: 9.67406e-06 | K40: 9.67239e-06
A41: ='wat types'!$A$7 -> n2(aq)(p) | B41: 5.53338e-06 | C41: 1.42103e-06 | D41: 4.75536e-07 | E41: 2.4789e-07 | F41: 1.87421e-07 | G41: 1.70657e-07 | H41: 1.65988e-07 | I41: 1.64698e-07 | J41: 1.64347e-07 | K41: 1.64258e-07
A42: ='wat types'!$A$8 -> ca+2 | B42: 0.00676399 | C42: 0.00696129 | D42: 0.00702897 | E42: 0.00705034 | F42: 0.00705675 | G42: 0.00705861 | H42: 0.00705914 | I42: 0.00705929 | J42: 0.00705933 | K42: 0.00705934
...

Sheet figures
