Workbook

Sheet README
A1: This excel sheet contains the results of a 1D denitrification problem without the whole path (2 redox reactions only). The input and output files can be found in the folder "denit_2reacts".
A3: The infiltration water is in equilibrium with atmospheric O2 & CO2
A5: We assume that the partial pressure of gases is constant
A6: We also assume that water has activity=1
A8: The domain is discretised by cells, who begin and end in the domain's boundary
A10: This problem has been simulated with the code REMIX, and the results are shown in the sheet "results"
A12: the BCs are prescribed mass flux at the inlet, and zero dispersive flux at the outlet
A14: concentrations of aqueous species are expressed in molalities
A16: The equilibrium reaction rates are computed using ordinary least squares method with the concentrations of variable activity species
A18: the kinetic reaction rates are computed using Monod expressions
A20: both transport and reactions are solved using Euler fully implicit

Sheet transport
A1: Delta_x | B1: =$B$3/($E$6) -> 0.1 | C1: m | D1: theta_t | E1: 1 | G1: t_c | H1: =$B$6*$B$4/($B$5^2) -> 2.5 | I1: d | K1: T_{i,i-1} | L1: =$B$5/(2*$B$1)+$B$6/($B$1^2) -> 21 | M1: 1/d | O1: A_{i,i-1} | P1: =-$B$2*L1/$B$4 -> -0.42
A2: Delta_t | B2: 0.01 | C2: d | G2: L_c | H2: =$B$7 -> 1 | I2: m | K2: T_{i,i+1} | L2: =-$B$5/(2*$B$1)+$B$6/($B$1^2) -> 19 | O2: A_{i,i+1} | P2: =-$B$2*L2/$B$4 -> -0.38
A3: L | B3: 1 | C3: m | D3: courant | E3: =B5*B2/(B4*B1) -> 0.04 | K3: T_{i,i} | L3: =-L2-L1 -> -40 | O3: A_{i,i} | P3: =1-$B$2*L3/$B$4 -> 1.8
A4: phi | B4: 0.5 | D4: Peclet | E4: =ABS(B5)*B1/B6 -> 0.1 | G4: q_inf | H4: =$B$5 -> 0.2 | I4: =C5 -> m/d | K4: T_{1,1} | L4: =-$B$5/(2*$B$1)-$B$6/($B$1^2) -> -21
A5: q | B5: 0.2 | C5: m/d | K5: T_{n,n} | L5: =-$L$1 -> -21
A6: D | B6: =$B$5*$B$7 -> 0.2 | C6: m^2/d | D6: num cells | E6: 10 | G6: transport approach | H6: Eulerian
A7: long disp | B7: 1 | C7: m
A8: initial target waters
A9: tar wat ind | B9: init wat type | C9: init min zone
A10: 1 | B10: 1 | D10: inflow
A11: 2 | B11: 2 | C11: 1 | D11: domain
A12: 3 | B12: 2 | C12: 1
A13: 4 | B13: 2 | C13: 1
A14: 5 | B14: 2 | C14: 1
A15: 6 | B15: 2 | C15: 1
A16: 7 | B16: 2 | C16: 1
A17: 8 | B17: 2 | C17: 1
A18: 9 | B18: 2 | C18: 1
A19: 10 | B19: 2 | C19: 1
A20: 11 | B20: 2 | C20: 1
A21: 12 | B21: 2 | D21: outflow
A22: BC inflow
A28: BC outflow

Sheet lambdas
A1: sum | B1: lambdas | C1: inf | D1: 1 | E1: 2 | F1: 3 | G1: 4 | H1: 5 | I1: 6 | J1: 7 | K1: 8 | L1: 9 | M1: 10 | N1: out
A2: =SUM(C2:N2) -> 1 | B2: 1 | C2: 0.030155137 | D2: 0.75387844 | E2: 0.16787472 | F2: 0.037382579 | G2: 0.0083244056 | H2: 0.0018536906 | I2: 0.00041278321 | J2: 9.1922237e-05 | K2: 2.0481924e-05 | L2: 4.6119372e-06 | M2: 1.2341804e-06 | N2: 0
A3: =SUM(C3:N3) -> 1 | B3: 2 | C3: 0.0074218296 | D3: 0.18554574 | E3: 0.62732131 | F3: 0.1396928 | G3: 0.03110699 | H3: 0.0069269491 | I3: 0.0015425057 | J3: 0.00034349888 | K3: 7.6537717e-05 | L3: 1.7234081e-05 | M3: 4.6119372e-06 | N3: 0
A4: =SUM(C4:N4) -> 1 | B4: 3 | C4: 0.0018266723 | D4: 0.045666807 | E4: 0.1543973 | F4: 0.62038513 | G4: 0.13814824 | H4: 0.030763048 | I4: 0.0068503717 | J4: 0.0015255017 | K4: 0.00033990916 | L4: 7.6537717e-05 | M4: 2.0481924e-05 | N4: 0
A5: =SUM(C5:N5) -> 1 | B5: 4 | C5: 0.00044958344 | D5: 0.011239586 | E5: 0.038000505 | F5: 0.15269016 | G5: 0.62000498 | H5: 0.1380636 | I5: 0.030744254 | J5: 0.0068464041 | K5: 0.0015255017 | L5: 0.00034349888 | M5: 9.1922237e-05 | N5: 0
A6: =SUM(C6:N6) -> 1 | B6: 5 | C6: 0.00011065219 | D6: 0.0027663048 | E6: 0.0093527447 | F6: 0.037580344 | G6: 0.15259661 | H6: 0.61998421 | I6: 0.13805922 | J6: 0.030744254 | K6: 0.0068503717 | L6: 0.0015425057 | M6: 0.00041278321 | N6: 0
A7: =SUM(C7:N7) -> 1 | B7: 6 | C7: 2.723394e-05 | D7: 0.0006808485 | E7: 0.0023019164 | F7: 0.0092493501 | G7: 0.037557386 | H7: 0.15259176 | I7: 0.61998421 | J7: 0.1380636 | K7: 0.030763048 | L7: 0.0069269491 | M7: 0.0018536906 | N7: 0
A8: =SUM(C8:N8) -> 1 | B8: 7 | C8: 6.7030852e-06 | D8: 0.00016757713 | E8: 0.00056657029 | F8: 0.002276541 | G8: 0.0092439931 | H8: 0.037557386 | I8: 0.15259661 | J8: 0.62000498 | K8: 0.13814824 | L8: 0.03110699 | M8: 0.0083244056 | N8: 0
A9: =SUM(C9:N9) -> 1 | B9: 8 | C9: 1.6507853e-06 | D9: 4.1269633e-05 | E9: 0.00013953067 | F9: 0.00056064937 | G9: 0.002276541 | H9: 0.0092493501 | I9: 0.037580344 | J9: 0.15269016 | K9: 0.62038513 | L9: 0.1396928 | M9: 0.037382579 | N9: 0
A10: =SUM(C10:N10) -> 1 | B10: 9 | C10: 4.1083641e-07 | D10: 1.027091e-05 | E10: 3.4725459e-05 | F10: 0.00013953067 | G10: 0.00056657029 | H10: 0.0023019164 | I10: 0.0093527447 | J10: 0.038000505 | K10: 0.1543973 | L10: 0.62732131 | M10: 0.16787472 | N10: 0
A11: =SUM(C11:N11) -> 1 | B11: 10 | C11: 1.2151499e-07 | D11: 3.0378749e-06 | E11: 1.027091e-05 | F11: 4.1269633e-05 | G11: 0.00016757713 | H11: 0.0006808485 | I11: 0.0027663048 | J11: 0.011239586 | K11: 0.045666807 | L11: 0.18554574 | M11: 0.75387844 | N11: 0

Sheet chem
A1: theta_r | B1: 1 | E1: h+ | F1: cl- | G1: no3- | H1: n2(aq)(p) | I1: ch2o(aq) | J1: hco3- | K1: o2(aq) | L1: co3-2 | M1: h2o
D2: S_k | E2: 1 | F2: 0 | G2: 0 | H2: 0 | I2: -1 | J2: 1 | K2: -1 | L2: 0 | M2: 0
A3: aqueous species | B3: ='wat types'!A2 -> h2o(p) | E3: 0.2 | F3: 0 | G3: -0.8 | H3: 0.4 | I3: -1 | J3: 1 | K3: 0 | L3: 0 | M3: 0.4
B4: ='wat types'!A3 -> h+
B5: ='wat types'!A4 -> cl- | D5: mu_1 | E5: 0.5 | F5: K_DOC | G5: 0.001 | H5: K_O2 | I5: 1e-05
B6: ='wat types'!A5 -> no3- | D6: mu_2 | E6: 2 | F6: K_DOC | G6: 0.0014 | H6: K_NO3 | I6: 0.0059 | J6: I_O2 | K6: 2.52e-05
B7: ='wat types'!A6 -> n2(aq)(p)
B8: ='wat types'!A7 -> ch2o(aq)
B9: ='wat types'!A8 -> hco3-
B10: ='wat types'!A9 -> o2(aq)
B11: ='wat types'!A10 -> co3-2
C13: part press
A14: gases | B14: co2(g) | C14: 0.00035
B15: o2(g) | C15: 0.2
A17: act coeffs model | B17: ideal
A19: equilibrium reactions | G19: K | H19: K master25
B20: co2(g) | G20: =1/(H20*C14) -> 1.8600814e+11 | H20: =10^(-7.8136) -> 1.5360311e-08
B21: o2(g) | G21: =1/(H21*C15) -> 3953.3931 | H21: =10^(-2.898) -> 0.0012647363
B22: co3-2 | G22: =1/H22 -> 4.6902933e-11 | H22: =10^(10.3288) -> 2.1320628e+10
A24: kinetic reactions | B24: aerobic oxidation of DOC
B25: denitrification
A27: reactive zone 1
C28: =E1 -> h+ | D28: =F1 -> cl- | E28: =G1 -> no3- | F28: =H1 -> n2(aq)(p) | G28: =I1 -> ch2o(aq) | H28: =J1 -> hco3- | I28: =K1 -> o2(aq) | J28: =L1 -> co3-2 | K28: =M1 -> h2o | L28: K
B29: S_e | C29: 1 | D29: 0 | E29: 0 | F29: 0 | G29: 0 | H29: 0 | I29: -1 | J29: 1 | K29: 0 | L29: =1/H22 -> 4.6902933e-11
B31: U | C31: 1 | D31: 0 | E31: 0 | F31: 0 | G31: 0 | H31: 0 | I31: 0 | J31: -1
C32: 0 | D32: 1 | E32: 0 | F32: 0 | G32: 0 | H32: 0 | I32: 0 | J32: 0
C33: 0 | D33: 0 | E33: 1 | F33: 0 | G33: 0 | H33: 0 | I33: 0 | J33: 0
C34: 0 | D34: 0 | E34: 0 | F34: 1 | G34: 0 | H34: 0 | I34: 0 | J34: 0
C35: 0 | D35: 0 | E35: 0 | F35: 0 | G35: 1 | H35: 0 | I35: 0 | J35: 0
C36: 0 | D36: 0 | E36: 0 | F36: 0 | G36: 0 | H36: 1 | I36: 0 | J36: 1
C37: 0 | D37: 0 | E37: 0 | F37: 0 | G37: 0 | H37: 0 | I37: 1 | J37: 0
B39: eq reactions | C39: co3-2
B41: prim species | C41: h+
C42: cl-
C43: no3-
C44: n2(aq)(p)
C45: ch2o(aq)
C46: hco3-
C47: o2(aq)

Sheet wat types
A1: aq species conc | B1: infiltration water | C1: initial water
A2: h2o(p) | B2: 55.5556 | C2: 55.5556
A3: h+ | B3: 1e-08 | C3: 1e-07
A4: cl- | B4: 0.001 | C4: 1e-16
A5: no3- | B5: 0.001 | C5: 1e-05
A6: n2(aq)(p) | B6: 1e-16 | C6: 1e-16
A7: ch2o(aq) | B7: 0.002 | C7: 1e-05
A8: hco3- | B8: 0.000537611 | C8: 0.001
A9: o2(aq) | B9: 0.000252947 | C9: 1e-06
A10: co3-2 | B10: 2.52155e-06 | C10: 4.69029e-07
A11: err abs
A12: co2(g) | B12: =ABS(1-B3*B8/(chem!$C$14*chem!$H$20)) -> 2.3449161e-07
A13: o2(g) | B13: =ABS(1-B9/(chem!$C$15*chem!$H$21)) -> 1.0654166e-06

Sheet results
A1: cell | B1: 1 | C1: 2 | D1: 3 | E1: 4 | F1: 5 | G1: 6 | H1: 7 | I1: 8 | J1: 9 | K1: 10
A2: x | B2: =transport!$B$1*(B$1-0.5) -> 0.05 | C2: =transport!$B$1*(C$1-0.5) -> 0.15 | D2: =transport!$B$1*(D$1-0.5) -> 0.25 | E2: =transport!$B$1*(E$1-0.5) -> 0.35 | F2: =transport!$B$1*(F$1-0.5) -> 0.45 | G2: =transport!$B$1*(G$1-0.5) -> 0.55 | H2: =transport!$B$1*(H$1-0.5) -> 0.65 | I2: =transport!$B$1*(I$1-0.5) -> 0.75 | ... K2: =transport!$B$1*(K$1-0.5) -> 0.95
A5: aq species conc | B5: t=0
A6: ='wat types'!$A$2 -> h2o(p) | B6: 55.5556 | C6: 55.5556 | D6: 55.5556 | E6: 55.5556 | F6: 55.5556 | G6: 55.5556 | H6: 55.5556 | I6: 55.5556 | J6: 55.5556 | K6: 55.5556
A7: ='wat types'!$A$3 -> h+ | B7: 1e-07 | C7: 1e-07 | D7: 1e-07 | E7: 1e-07 | F7: 1e-07 | G7: 1e-07 | H7: 1e-07 | I7: 1e-07 | J7: 1e-07 | K7: 1e-07
A8: ='wat types'!$A$4 -> cl- | B8: 1e-16 | C8: 1e-16 | D8: 1e-16 | E8: 1e-16 | F8: 1e-16 | G8: 1e-16 | H8: 1e-16 | I8: 1e-16 | J8: 1e-16 | K8: 1e-16
A9: ='wat types'!$A$5 -> no3- | B9: 1e-05 | C9: 1e-05 | D9: 1e-05 | E9: 1e-05 | F9: 1e-05 | G9: 1e-05 | H9: 1e-05 | I9: 1e-05 | J9: 1e-05 | K9: 1e-05
A10: ='wat types'!$A$6 -> n2(aq)(p) | B10: 1e-16 | C10: 1e-16 | D10: 1e-16 | E10: 1e-16 | F10: 1e-16 | G10: 1e-16 | H10: 1e-16 | I10: 1e-16 | J10: 1e-16 | K10: 1e-16
A11: ='wat types'!$A$7 -> ch2o(aq) | B11: 1e-05 | C11: 1e-05 | D11: 1e-05 | E11: 1e-05 | F11: 1e-05 | G11: 1e-05 | H11: 1e-05 | I11: 1e-05 | J11: 1e-05 | K11: 1e-05
A12: ='wat types'!$A$8 -> hco3- | B12: 0.001 | C12: 0.001 | D12: 0.001 | E12: 0.001 | F12: 0.001 | G12: 0.001 | H12: 0.001 | I12: 0.001 | J12: 0.001 | K12: 0.001
A13: ='wat types'!$A$9 -> o2(aq) | B13: 1e-06 | C13: 1e-06 | D13: 1e-06 | E13: 1e-06 | F13: 1e-06 | G13: 1e-06 | H13: 1e-06 | I13: 1e-06 | J13: 1e-06 | K13: 1e-06
A14: ='wat types'!$A$10 -> co3-2 | B14: 4.69029e-07 | C14: 4.69029e-07 | D14: 4.69029e-07 | E14: 4.69029e-07 | F14: 4.69029e-07 | G14: 4.69029e-07 | H14: 4.69029e-07 | I14: 4.69029e-07 | J14: 4.69029e-07 | K14: 4.69029e-07
A15: vol frac
A19: calcite | B19: 0.5 | C19: 0.5 | D19: 0.5 | E19: 0.5 | F19: 0.5 | G19: 0.5 | H19: 0.5 | I19: 0.5 | J19: 0.5 | K19: 0.5
A20: aq species conc | B20: t=0.01d | L20: error abs
A21: ='wat types'!$A$2 -> h2o(p) | B21: 55.5556 | C21: 55.5556 | D21: 55.5556 | E21: 55.5556 | F21: 55.5556 | G21: 55.5556 | H21: 55.5556 | I21: 55.5556 | J21: 55.5556 | K21: 55.5556
A22: ='wat types'!$A$3 -> h+ | B22: 8.75932e-06 | C22: 2.4122e-06 | D22: 9.86845e-07 | E22: 6.669e-07 | F22: 5.92839e-07 | G22: 5.75012e-07 | H22: 5.70652e-07 | I22: 5.6958e-07 | J22: 5.69317e-07 | K22: 5.69256e-07
A23: ='wat types'!$A$4 -> cl- | B23: 3.01551e-05 | C23: 7.42183e-06 | D23: 1.82667e-06 | E23: 4.49583e-07 | F23: 1.10652e-07 | G23: 2.72339e-08 | H23: 6.70309e-09 | I23: 1.65079e-09 | J23: 4.10837e-10 | K23: 1.21515e-10 | L23: =ABS(B23-SUMPRODUCT($B$8:$K$8,lambdas!$D$2:$M$2)-'wat types'!$B$4*lambdas!$C$2) -> 3.748921e-11 | M23: =ABS(C23-SUMPRODUCT($B$8:$K$8,lambdas!$D$3:$M$3)-'wat types'!$B$4*lambdas!$C$3) -> 4.3532049e-13 | N23: =ABS(D23-SUMPRODUCT($B$8:$K$8,lambdas!$D$4:$M$4)-'wat types'!$B$4*lambdas!$C$4) -> 2.2917234e-12 | O23: =ABS(E23-SUMPRODUCT($B$8:$K$8,lambdas!$D$5:$M$5)-'wat types'!$B$4*lambdas!$C$5) -> 4.4167585e-13 | P23: =ABS(F23-SUMPRODUCT($B$8:$K$8,lambdas!$D$6:$M$6)-'wat types'!$B$4*lambdas!$C$6) -> 1.9050707e-13 | Q23: =ABS(G23-SUMPRODUCT($B$8:$K$8,lambdas!$D$7:$M$7)-'wat types'!$B$4*lambdas!$C$7) -> 4.0286502e-14
A24: ='wat types'!$A$5 -> no3- | B24: 3.61901e-05 | C24: 1.66825e-05 | D24: 1.15443e-05 | E24: 1.02549e-05 | F24: 9.93594e-06 | G24: 9.85734e-06 | H24: 9.83799e-06 | I24: 9.83323e-06 | J24: 9.83206e-06 | K24: 9.83179e-06
A25: ='wat types'!$A$6 -> n2(aq)(p) | B25: 1.83174e-06 | C25: 3.32534e-07 | D25: 1.3205e-07 | E25: 9.51071e-08 | F25: 8.68047e-08 | G25: 8.48097e-08 | H25: 8.43216e-08 | I25: 8.42017e-08 | J25: 8.41723e-08 | K25: 8.41654e-08
A26: ='wat types'!$A$7 -> ch2o(aq) | B26: 5.71576e-05 | C26: 2.13267e-05 | D26: 1.20588e-05 | E26: 9.73799e-06 | F26: 9.16371e-06 | G26: 9.02216e-06 | H26: 8.98731e-06 | I26: 8.97873e-06 | J26: 8.97663e-06 | K26: 8.97614e-06
A27: ='wat types'!$A$8 -> hco3- | B27: 0.000999433 | C27: 0.00100048 | D27: 0.00100116 | E27: 0.00100135 | F27: 0.0010014 | G27: 0.00100141 | H27: 0.00100141 | I27: 0.00100141 | J27: 0.00100141 | K27: 0.00100141
A28: ='wat types'!$A$9 -> o2(aq) | B28: 3.25771e-07 | C28: 2.58503e-07 | D28: 2.14045e-07 | E28: 1.94357e-07 | F28: 1.88401e-07 | G28: 1.8685e-07 | H28: 1.86462e-07 | I28: 1.86366e-07 | J28: 1.86343e-07 | K28: 1.86337e-07
A29: ='wat types'!$A$10 -> co3-2 | B29: 5.3516e-09 | C29: 1.94533e-08 | D29: 4.75831e-08 | E29: 7.04246e-08 | F29: 7.92261e-08 | G29: 8.16833e-08 | H29: 8.23078e-08 | I29: 8.24627e-08 | J29: 8.25007e-08 | K29: 8.25096e-08
A30: r_eq
A31: co3-2 | B31: -5.41913e-05 | C31: -4.68285e-05 | D31: -4.25974e-05 | E31: -3.99707e-05 | F31: -3.90073e-05 | G31: -3.87412e-05 | H31: -3.86738e-05 | I31: -3.86571e-05 | J31: -3.8653e-05 | K31: -3.8652e-05 | L31: =ABS(1-B22*B29/(B27*chem!$L$29)) -> 8.113758e-07 | M31: =ABS(1-C22*C29/(C27*chem!$L$29)) -> 4.1765902e-06 | N31: =ABS(1-D22*D29/(D27*chem!$L$29)) -> 4.1723656e-06 | O31: =ABS(1-E22*E29/(E27*chem!$L$29)) -> 1.832378e-06 | P31: =ABS(1-F22*F29/(F27*chem!$L$29)) -> 5.8560121e-06 | Q31: =ABS(1-G22*G29/(G27*chem!$L$29)) -> 4.008517e-06 | R31: =ABS(1-H22*H29/(H27*chem!$L$29)) -> 9.5189674e-07 | S31: =ABS(1-I22*I29/(I27*chem!$L$29)) -> 8.237358e-07 | ... U31: =ABS(1-K22*K29/(K27*chem!$L$29)) -> 4.0200291e-07
A32: rk
A33: oxid aer | B33: 0.000852892 | C33: 0.000263093 | D33: 0.000124846 | E33: 9.19328e-05 | F33: 8.3957e-05 | G33: 8.20034e-05 | H33: 8.15232e-05 | I33: 8.14051e-05 | J33: 8.13761e-05 | K33: 8.13693e-05 | L33: =ABS(B33-chem!$E$5*B26*B28/((chem!$G$5+B26)*(chem!$I$5+B28))) -> 2.8235413e-10 | M33: =ABS(C33-chem!$E$5*C26*C28/((chem!$G$5+C26)*(chem!$I$5+C28))) -> 7.7735229e-10 | N33: =ABS(D33-chem!$E$5*D26*D28/((chem!$G$5+D26)*(chem!$I$5+D28))) -> 2.9875018e-10 | O33: =ABS(E33-chem!$E$5*E26*E28/((chem!$G$5+E26)*(chem!$I$5+E28))) -> 1.0441802e-10 | P33: =ABS(F33-chem!$E$5*F26*F28/((chem!$G$5+F26)*(chem!$I$5+F28))) -> 4.1479248e-12 | Q33: =ABS(G33-chem!$E$5*G26*G28/((chem!$G$5+G26)*(chem!$I$5+G28))) -> 2.183334e-10 | R33: =ABS(H33-chem!$E$5*H26*H28/((chem!$G$5+H26)*(chem!$I$5+H28))) -> 4.2705166e-11 | S33: =ABS(I33-chem!$E$5*I26*I28/((chem!$G$5+I26)*(chem!$I$5+I28))) -> 2.4392389e-10 | ... U33: =ABS(K33-chem!$E$5*K26*K28/((chem!$G$5+K26)*(chem!$I$5+K28))) -> 1.4898001e-10
A34: denit | B34: 0.000472173 | C34: 8.37551e-05 | D34: 3.3073e-05 | E34: 2.37875e-05 | F34: 2.17036e-05 | G34: 2.1203e-05 | H34: 2.10805e-05 | I34: 2.10505e-05 | J34: 2.10431e-05 | K34: 2.10414e-05 | L34: =ABS(B34-chem!$E$6*B26*B24*chem!$K$6/((chem!$G$6+B26)*(chem!$I$6+B24)*(chem!$K$6+results!B28))) -> 4.3263508e-11 | M34: =ABS(C34-chem!$E$6*C26*C24*chem!$K$6/((chem!$G$6+C26)*(chem!$I$6+C24)*(chem!$K$6+results!C28))) -> 1.8781702e-10 | N34: =ABS(D34-chem!$E$6*D26*D24*chem!$K$6/((chem!$G$6+D26)*(chem!$I$6+D24)*(chem!$K$6+results!D28))) -> 8.5086173e-11 | O34: =ABS(E34-chem!$E$6*E26*E24*chem!$K$6/((chem!$G$6+E26)*(chem!$I$6+E24)*(chem!$K$6+results!E28))) -> 3.578249e-11 | P34: =ABS(F34-chem!$E$6*F26*F24*chem!$K$6/((chem!$G$6+F26)*(chem!$I$6+F24)*(chem!$K$6+results!F28))) -> 2.5795169e-11 | Q34: =ABS(G34-chem!$E$6*G26*G24*chem!$K$6/((chem!$G$6+G26)*(chem!$I$6+G24)*(chem!$K$6+results!G28))) -> 7.495063e-12 | R34: =ABS(H34-chem!$E$6*H26*H24*chem!$K$6/((chem!$G$6+H26)*(chem!$I$6+H24)*(chem!$K$6+results!H28))) -> 4.3263516e-11 | S34: =ABS(I34-chem!$E$6*I26*I24*chem!$K$6/((chem!$G$6+I26)*(chem!$I$6+I24)*(chem!$K$6+results!I28))) -> 4.6998569e-11 | ... U34: =ABS(K34-chem!$E$6*K26*K24*chem!$K$6/((chem!$G$6+K26)*(chem!$I$6+K24)*(chem!$K$6+results!K28))) -> 3.3145677e-11
A35: aq species conc | B35: t=0.02d | L35: error abs
A36: ='wat types'!$A$2 -> h2o(p) | B36: 55.5556 | C36: 55.5556 | D36: 55.5556 | E36: 55.5556 | F36: 55.5556 | G36: 55.5556 | H36: 55.5556 | I36: 55.5556 | J36: 55.5556 | K36: 55.5556
A37: ='wat types'!$A$3 -> h+ | B37: 1.67438e-05 | C37: 5.71567e-06 | D37: 2.20439e-06 | E37: 1.15835e-06 | F37: 8.58763e-07 | G37: 7.74038e-07 | H37: 7.50206e-07 | I37: 7.43571e-07 | J37: 7.41751e-07 | K37: 7.41287e-07
A38: ='wat types'!$A$4 -> cl- | B38: 5.42066e-05 | C38: 1.79428e-05 | D38: 5.54862e-06 | E38: 1.64437e-06 | F38: 4.73317e-07 | G38: 1.33379e-07 | H38: 3.69852e-08 | I38: 1.01349e-08 | J38: 2.78503e-09 | K38: 9.09315e-10 | L38: =ABS(B38-SUMPRODUCT($B$23:$K$23,lambdas!$D$2:$M$2)-'wat types'!$B$4*lambdas!$C$2) -> 8.6935213e-14 | M38: =ABS(C38-SUMPRODUCT($B$23:$K$23,lambdas!$D$3:$M$3)-'wat types'!$B$4*lambdas!$C$3) -> 2.0727769e-11 | N38: =ABS(D38-SUMPRODUCT($B$23:$K$23,lambdas!$D$4:$M$4)-'wat types'!$B$4*lambdas!$C$4) -> 6.6711527e-13 | O38: =ABS(E38-SUMPRODUCT($B$23:$K$23,lambdas!$D$5:$M$5)-'wat types'!$B$4*lambdas!$C$5) -> 1.3328165e-12 | P38: =ABS(F38-SUMPRODUCT($B$23:$K$23,lambdas!$D$6:$M$6)-'wat types'!$B$4*lambdas!$C$6) -> 5.5575785e-14 | Q38: =ABS(G38-SUMPRODUCT($B$23:$K$23,lambdas!$D$7:$M$7)-'wat types'!$B$4*lambdas!$C$7) -> 4.215281e-13
A39: ='wat types'!$A$5 -> no3- | B39: 5.25978e-05 | C39: 2.49213e-05 | D39: 1.45421e-05 | E39: 1.11321e-05 | F39: 1.00937e-05 | G39: 9.79073e-06 | H39: 9.70464e-06 | I39: 9.68064e-06 | J39: 9.67406e-06 | K39: 9.67239e-06
A40: ='wat types'!$A$6 -> n2(aq)(p) | B40: 5.53338e-06 | C40: 1.42103e-06 | D40: 4.75536e-07 | E40: 2.4789e-07 | F40: 1.87421e-07 | G40: 1.70657e-07 | H40: 1.65988e-07 | I40: 1.64698e-07 | J40: 1.64347e-07 | K40: 1.64258e-07
A41: ='wat types'!$A$7 -> ch2o(aq) | B41: 8.95782e-05 | C41: 3.67492e-05 | D41: 1.75267e-05 | E41: 1.12862e-05 | F41: 9.39297e-06 | G41: 8.84146e-06 | H41: 8.68494e-06 | I41: 8.64134e-06 | J41: 8.62941e-06 | K41: 8.62636e-06
A42: ='wat types'!$A$8 -> hco3- | B42: 0.00100381 | C42: 0.00100116 | D42: 0.00100141 | E42: 0.00100166 | F42: 0.00100175 | G42: 0.00100177 | H42: 0.00100178 | I42: 0.00100178 | J42: 0.00100178 | K42: 0.00100178
A43: ='wat types'!$A$9 -> o2(aq) | B43: 1.97702e-07 | C43: 1.16237e-07 | D43: 7.17243e-08 | E43: 4.78992e-08 | F43: 3.88669e-08 | G43: 3.6282e-08 | H43: 3.56292e-08 | I43: 3.54712e-08 | J43: 3.54336e-08 | K43: 3.54251e-08
A44: ='wat types'!$A$10 -> co3-2 | B44: 2.81187e-09 | C44: 8.21553e-09 | D44: 2.1307e-08 | E44: 4.05584e-08 | F44: 5.47122e-08 | G44: 6.07024e-08 | H44: 6.26313e-08 | I44: 6.31903e-08 | J44: 6.33453e-08 | K44: 6.3385e-08
A45: r_eq
...

Sheet figures
